Workbook

Sheet README & Settings
A1: Senior Authority Daily Checklist & Escalation System
A2: Independent workbook — separate from the existing Task Delegation system
A5: HOW THIS WORKBOOK WORKS
A6: 1. Employees | B6: Master list of employees/supervisors — the ONLY place you add a new person.
A7: 2. Task Master | B7: Recurring assignment definitions: Daily/Weekly/Monthly, mapped to Employee + Supervisor.
A8: 3. Today's Assignment Queue | B8: Auto-generated draft of today's tasks per employee. MANAGER REVIEWS THIS FIRST — untick 'Include Today' to drop a task, or add an ad-hoc row for a one-off task, before it's locked and sent to the Senior Authority as the checklist form. This is how you change what's assigned on a given day.
A9: 4. Daily Checklist | B9: The finalized, locked record of every task instance for the day, per employee, per task — one row each. Shows Status, Senior Remarks (from the form) AND Employee Response (their WhatsApp reply to a reminder) side by side, so the manager sees both sides in one place.
A10: 5. Employee Day-Wise Tracker | B10: One row per employee, one column per day — shows completion as 'Done/Total' (e.g. 3/5) plus color, so a partially-completed day is visible at a glance, not just pass/fail.
A11: 6. Form Responses | B11: Raw Google Form submissions from the Senior Authority land here.
A12: 7. Escalation Log | B12: Every escalation to a Supervisor is recorded here for audit.
A13: 8. Dashboard | B13: Live rollup with color-coded status counts for today.
A14: 9. Holiday Calendar | B14: Company holidays that pause Daily-cadence expansion (Sundays are hardcoded separately).
A15: 10. Task Pause Log | B15: Put a task on hold for a date range (employee leave, etc.) instead of un-ticking it in the Queue every day.
A16: 11. Reassignment History | B16: Audit trail for moving a recurring task from one employee to another mid-cycle.
A17: 12. Employee Scorecard | B17: 7-day / 30-day completion % and escalation trend per employee, for spotting chronic under-performers at a glance.
A18: 13. Access Control Log | B18: Lightweight record of who has what access, since Sheets' own sharing UI doesn't self-document.
A20: COLOR KEY FOR EDITABLE CELLS
A21: Yellow fill | B21: Direct manual input (Employees, Task Master)
A22: Blue fill | B22: Manager review/decision cells (Today's Assignment Queue) — this is your daily control point
A24: Setting | B24: Value
A25: ESCALATION_THRESHOLD_DEFAULT | B25: 2 | C25: Reminders sent to employee before auto-escalating to supervisor
A26: REMINDER_INTERVAL_HOURS | B26: 4 | C26: Hours between reminders to employee on a Not-Done task
A27: ASSIGNMENT_QUEUE_LOCK_TIME_IST | B27: 08:30 | C27: Time n8n locks the Queue and generates the Daily Checklist
A28: DAILY_FORM_SEND_TIME_IST | B28: 09:00 | C28: Time the checklist form link is sent to Senior Authority
A29: EOD_CUTOFF_TIME_IST | B29: 19:00 | C29: Time after which a Pending task is marked Not Done / Red
A30: TIMEZONE | B30: Asia/Kolkata | C30: All schedules run in this timezone
A31: WHATSAPP_PHONE_NUMBER_ID | B31: 1158085794064004 | C31: Same WABA number as existing system
A32: SENIOR_AUTHORITY_NAME | B32: Satyam Sharma | C32: Person who fills the daily checklist form
A33: SENIOR_AUTHORITY_PHONE | B33: 919798637485 | C33: Receives the daily form link
A34: REMINDER_INTERVAL_HOURS_HIGH | B34: 2 | C34: Hours between reminders for High-priority tasks (faster cadence than standard)
A35: MAX_REMINDERS_PER_DAY_HIGH | B35: 4 | C35: Cap on reminders/day for High-priority tasks; escalation should fire before this is hit
A36: ESCALATION_TIER_2_ENABLED | B36: N | C36: Y/N — governs whether Supervisor->Plant Head 2nd-tier escalation is active. N today (single-tier org).
A38: v5 DESIGN NOTES
A39: Priority (High/Medium/Low) added to Task Master — drives reminder interval and escalation speed (a floor, not a ceiling).
A40: New sheets: Holiday Calendar, Task Pause Log, Reassignment History, Employee Scorecard, Access Control Log.
A41: Assignment Queue is now a hard gate: Locked At is system-set at auto-lock (see n8n Trigger 1B) — do not hand-edit.
A42: T-Y-002 'Finalise & File Balance Sheet' Schedule Detail is '20' with no month specified — FLAG: needs a real month from you before Yearly automation can handle it (kept as manual placeholder for now).
A44: v7 DESIGN NOTES
A45: Employee roster replaced with the 13-person staff list (Name/Department/Designation) supplied Sep 2026 — see Employees tab. Role/Category column renamed Designation; new Department column added (col I) so existing Task Master VLOOKUPs (cols B/D/E) were not disturbed.
A46: Employees whose names changed (Aparna -> Aparna Kumari, Accounts Executive (TBD) -> Rajeshwar Pandey) have had every existing Task Master row updated to the new name so VLOOKUPs keep resolving.
...

Sheet Employees
A1: Employee Name | B1: Phone | C1: Designation | D1: Supervisor Name | E1: Supervisor Phone | F1: Active (Y/N) | G1: Plant Head Name | H1: Plant Head Phone | I1: Department
A2: Yogesh Tomar | B2: TBD - add phone number | C2: Plant Head | D2: Satyam Sharma | E2: 919798637485 | F2: Y | I2: Operation
A3: Santosh Guddu | B3: 918250685227 | C3: Operation Head | D3: Satyam Sharma | E3: 919798637485 | F3: Y | G3: Yogesh Tomar | H3: TBD - add phone number | I3: Production
A4: Satish Bhumihar | B4: TBD - add phone number | C4: Incharge | D4: Satyam Sharma | E4: 919798637485 | F4: Y | G4: Yogesh Tomar | H4: TBD - add phone number | I4: Production
A5: Sushmita Mukherjee | B5: 917903066993 | C5: EA to CEO | D5: Satyam Sharma | E5: 919798637485 | F5: Y | G5: Yogesh Tomar | H5: TBD - add phone number | I5: Admin
A6: Rajeshwar Pandey | B6: TBD - add phone number | C6: Sr. Accountant | D6: Satyam Sharma | E6: 919798637485 | F6: Y | G6: Yogesh Tomar | H6: TBD - add phone number | I6: Accounts
A7: Aparna Kumari | B7: 918092902442 | C7: Sr. Executive | D7: Satyam Sharma | E7: 919798637485 | F7: Y | G7: Yogesh Tomar | H7: TBD - add phone number | I7: Import
A8: Deb Kumar Nag | B8: TBD - add phone number | C8: HOD | D8: Satyam Sharma | E8: 919798637485 | F8: Y | G8: Yogesh Tomar | H8: TBD - add phone number | I8: Mech Maintenance
A9: Pratyush Nanda | B9: 918093556090 | C9: HOD | D9: Satyam Sharma | E9: 919798637485 | F9: Y | G9: Yogesh Tomar | H9: TBD - add phone number | I9: Elec Maintenance
A10: Om Kumar Choudhury | B10: TBD - add phone number | C10: Incharge | D10: Satyam Sharma | E10: 919798637485 | F10: Y | G10: Yogesh Tomar | H10: TBD - add phone number | I10: Raw Material
A11: Chandan Kumar | B11: 916205044831 | C11: HOD | D11: Satyam Sharma | E11: 919798637485 | F11: Y | G11: Yogesh Tomar | H11: TBD - add phone number | I11: Store
A12: Ravi Anand | B12: TBD - add phone number | C12: Manager | D12: Satyam Sharma | E12: 919798637485 | F12: Y | G12: Yogesh Tomar | H12: TBD - add phone number | I12: HR
A13: Shahin Sheikh | B13: TBD - add phone number | C13: Incharge | D13: Satyam Sharma | E13: 919798637485 | F13: Y | G13: Yogesh Tomar | H13: TBD - add phone number | I13: Dispatch
A14: Mobin Ansari | B14: TBD - add phone number | C14: Incharge | D14: Satyam Sharma | E14: 919798637485 | F14: Y | G14: Yogesh Tomar | H14: TBD - add phone number | I14: Dispatch

Sheet Task Master
A1: Task ID | B1: Employee Name | C1: Employee Phone | D1: Task Description | E1: Cadence (Daily/Weekly/Monthly) | F1: Schedule Detail (Weekday / Day-of-Month) | G1: Start Date | H1: End Date | I1: Active (Y/N) | J1: Supervisor Name | K1: Supervisor Phone | L1: Escalation Threshold | M1: Category | N1: Notes | O1: Priority (High/Medium/Low) | P1: Paused (Y/N — formula, do not hand-edit)
A2: T-D-001 | B2: Santosh Guddu | C2: =IFERROR(VLOOKUP(B2,Employees!$A:$B,2,FALSE()),"") -> 918250685227 | D2: Submit daily scrap procurement figures | E2: Daily | F2: Every day | G2: 2026-09-01 | H2: 2026-12-31 | I2: Y | J2: =IFERROR(VLOOKUP(B2,Employees!$A:$D,4,FALSE()),"") -> Satyam Sharma | K2: =IFERROR(VLOOKUP(B2,Employees!$A:$E,5,FALSE()),"") -> 919798637485 | L2: 2 | M2: Procurement | O2: Low | P2: =IF(SUMPRODUCT(('Task Pause Log'!$B$2:$B$500=$A2)*('Task Pause Log'!$I$2:$I$500="Y"))>0,"Y","N") -> N
A3: T-D-002 | B3: Santosh Guddu | C3: =IFERROR(VLOOKUP(B3,Employees!$A:$B,2,FALSE()),"") -> 918250685227 | D3: Update daily inbound scrap weighbridge log | E3: Daily | F3: Every day | G3: 2026-09-01 | H3: 2026-12-31 | I3: Y | J3: =IFERROR(VLOOKUP(B3,Employees!$A:$D,4,FALSE()),"") -> Satyam Sharma | K3: =IFERROR(VLOOKUP(B3,Employees!$A:$E,5,FALSE()),"") -> 919798637485 | L3: 2 | M3: Procurement | O3: Low | P3: =IF(SUMPRODUCT(('Task Pause Log'!$B$2:$B$500=$A3)*('Task Pause Log'!$I$2:$I$500="Y"))>0,"Y","N") -> N
A4: T-W-001 | B4: Chandan Kumar | C4: =IFERROR(VLOOKUP(B4,Employees!$A:$B,2,FALSE()),"") -> 916205044831 | D4: Submit weekly stock reconciliation report | E4: Weekly | F4: Monday | G4: 2026-09-01 | H4: 2026-12-31 | I4: Y | J4: =IFERROR(VLOOKUP(B4,Employees!$A:$D,4,FALSE()),"") -> Satyam Sharma | K4: =IFERROR(VLOOKUP(B4,Employees!$A:$E,5,FALSE()),"") -> 919798637485 | L4: 2 | M4: Operations | O4: Medium | P4: =IF(SUMPRODUCT(('Task Pause Log'!$B$2:$B$500=$A4)*('Task Pause Log'!$I$2:$I$500="Y"))>0,"Y","N") -> N
A5: T-W-002 | B5: Chandan Kumar | C5: =IFERROR(VLOOKUP(B5,Employees!$A:$B,2,FALSE()),"") -> 916205044831 | D5: Machine downtime log review | E5: Weekly | F5: Friday | G5: 2026-09-01 | H5: 2026-12-31 | I5: Y | J5: =IFERROR(VLOOKUP(B5,Employees!$A:$D,4,FALSE()),"") -> Satyam Sharma | K5: =IFERROR(VLOOKUP(B5,Employees!$A:$E,5,FALSE()),"") -> 919798637485 | L5: 2 | M5: Operations | O5: Medium | P5: =IF(SUMPRODUCT(('Task Pause Log'!$B$2:$B$500=$A5)*('Task Pause Log'!$I$2:$I$500="Y"))>0,"Y","N") -> N
A6: T-M-001 | B6: Sushmita Mukherjee | C6: =IFERROR(VLOOKUP(B6,Employees!$A:$B,2,FALSE()),"") -> 917903066993 | D6: Submit monthly quality audit summary | E6: Monthly | F6: 1 | G6: 2026-09-01 | H6: 2026-12-31 | I6: Y | J6: =IFERROR(VLOOKUP(B6,Employees!$A:$D,4,FALSE()),"") -> Satyam Sharma | K6: =IFERROR(VLOOKUP(B6,Employees!$A:$E,5,FALSE()),"") -> 919798637485 | L6: 3 | M6: Quality | O6: Medium | P6: =IF(SUMPRODUCT(('Task Pause Log'!$B$2:$B$500=$A6)*('Task Pause Log'!$I$2:$I$500="Y"))>0,"Y","N") -> N
A7: T-D-003 | B7: Sushmita Mukherjee | C7: =IFERROR(VLOOKUP(B7,Employees!$A:$B,2,FALSE()),"") -> 917903066993 | D7: Prepare & post Daily Production report in group | E7: Daily | F7: Every day | G7: 2026-09-01 | H7: 2026-12-31 | I7: Y | J7: =IFERROR(VLOOKUP(B7,Employees!$A:$D,4,FALSE()),"") -> Satyam Sharma | K7: =IFERROR(VLOOKUP(B7,Employees!$A:$E,5,FALSE()),"") -> 919798637485 | L7: 2 | M7: Reporting | N7: From JD item 1 | O7: Low | P7: =IF(SUMPRODUCT(('Task Pause Log'!$B$2:$B$500=$A7)*('Task Pause Log'!$I$2:$I$500="Y"))>0,"Y","N") -> N
A8: T-W-003 | B8: Sushmita Mukherjee | C8: =IFERROR(VLOOKUP(B8,Employees!$A:$B,2,FALSE()),"") -> 917903066993 | D8: Weekly report collection & reconciliation (Production & RM) | E8: Weekly | F8: Saturday | G8: 2026-09-01 | H8: 2026-12-31 | I8: Y | J8: =IFERROR(VLOOKUP(B8,Employees!$A:$D,4,FALSE()),"") -> Satyam Sharma | K8: =IFERROR(VLOOKUP(B8,Employees!$A:$E,5,FALSE()),"") -> 919798637485 | L8: 2 | M8: Reporting | N8: From JD item 8 | O8: Medium | P8: =IF(SUMPRODUCT(('Task Pause Log'!$B$2:$B$500=$A8)*('Task Pause Log'!$I$2:$I$500="Y"))>0,"Y","N") -> N
A9: T-M-002 | B9: Sushmita Mukherjee | C9: =IFERROR(VLOOKUP(B9,Employees!$A:$B,2,FALSE()),"") -> 917903066993 | D9: Prepare monthwise dispatch details & schedule vs dispatch data | E9: Monthly | F9: 28 | G9: 2026-09-01 | H9: 2026-12-31 | I9: Y | J9: =IFERROR(VLOOKUP(B9,Employees!$A:$D,4,FALSE()),"") -> Satyam Sharma | K9: =IFERROR(VLOOKUP(B9,Employees!$A:$E,5,FALSE()),"") -> 919798637485 | L9: 2 | M9: Reporting | N9: From JD items 4-5 | O9: Medium | P9: =IF(SUMPRODUCT(('Task Pause Log'!$B$2:$B$500=$A9)*('Task Pause Log'!$I$2:$I$500="Y"))>0,"Y","N") -> N
A10: T-W-004 | B10: Aparna Kumari | C10: =IFERROR(VLOOKUP(B10,Employees!$A:$B,2,FALSE()),"") -> 918092902442 | D10: Update Weekly Tracking Sheet | E10: Weekly | F10: Friday | G10: 2026-09-01 | H10: 2026-12-31 | I10: Y | J10: =IFERROR(VLOOKUP(B10,Employees!$A:$D,4,FALSE()),"") -> Satyam Sharma | K10: =IFERROR(VLOOKUP(B10,Employees!$A:$E,5,FALSE()),"") -> 919798637485 | L10: 2 | M10: Import/Logistics | N10: From JD item 1 | O10: Medium | P10: =IF(SUMPRODUCT(('Task Pause Log'!$B$2:$B$500=$A10)*('Task Pause Log'!$I$2:$I$500="Y"))>0,"Y","N") -> N
A11: T-M-003 | B11: Aparna Kumari | C11: =IFERROR(VLOOKUP(B11,Employees!$A:$B,2,FALSE()),"") -> 918092902442 | D11: Monthly overall data & NSO data compilation | E11: Monthly | F11: 25 | G11: 2026-09-01 | H11: 2026-12-31 | I11: Y | J11: =IFERROR(VLOOKUP(B11,Employees!$A:$D,4,FALSE()),"") -> Satyam Sharma | K11: =IFERROR(VLOOKUP(B11,Employees!$A:$E,5,FALSE()),"") -> 919798637485 | L11: 2 | M11: Import/Logistics | N11: From JD items 5,7 | O11: Medium | P11: =IF(SUMPRODUCT(('Task Pause Log'!$B$2:$B$500=$A11)*('Task Pause Log'!$I$2:$I$500="Y"))>0,"Y","N") -> N
A12: T-M-004 | B12: Aparna Kumari | C12: =IFERROR(VLOOKUP(B12,Employees!$A:$B,2,FALSE()),"") -> 918092902442 | D12: Marine Insurance monthly check | E12: Monthly | F12: 20 | G12: 2026-09-01 | H12: 2026-12-31 | I12: Y | J12: =IFERROR(VLOOKUP(B12,Employees!$A:$D,4,FALSE()),"") -> Satyam Sharma | K12: =IFERROR(VLOOKUP(B12,Employees!$A:$E,5,FALSE()),"") -> 919798637485 | L12: 2 | M12: Import/Logistics | N12: From JD item 11 | O12: Medium | P12: =IF(SUMPRODUCT(('Task Pause Log'!$B$2:$B$500=$A12)*('Task Pause Log'!$I$2:$I$500="Y"))>0,"Y","N") -> N
A13: T-D-004 | B13: Pratyush Nanda | C13: =IFERROR(VLOOKUP(B13,Employees!$A:$B,2,FALSE()),"") -> 918093556090 | D13: Electricity reading collection (JUSCO/JBVNL/Warehouse) | E13: Daily | F13: Every day | G13: 2026-09-01 | H13: 2026-12-31 | I13: Y | J13: =IFERROR(VLOOKUP(B13,Employees!$A:$D,4,FALSE()),"") -> Satyam Sharma | K13: =IFERROR(VLOOKUP(B13,Employees!$A:$E,5,FALSE()),"") -> 919798637485 | L13: 2 | M13: Maintenance | N13: From JD item 1 | O13: Low | P13: =IF(SUMPRODUCT(('Task Pause Log'!$B$2:$B$500=$A13)*('Task Pause Log'!$I$2:$I$500="Y"))>0,"Y","N") -> N
A14: T-M-005 | B14: Rajeshwar Pandey | C14: =IFERROR(VLOOKUP(B14,Employees!$A:$B,2,FALSE()),"") -> TBD - add phone number | D14: TDS/TCS Payment | E14: Monthly | F14: 7 | G14: 2026-09-01 | H14: 2026-12-31 | I14: Y | J14: =IFERROR(VLOOKUP(B14,Employees!$A:$D,4,FALSE()),"") -> Satyam Sharma | K14: =IFERROR(VLOOKUP(B14,Employees!$A:$E,5,FALSE()),"") -> 919798637485 | L14: 1 | M14: Accounts/Statutory | N14: From Accounts Checklist | O14: High | P14: =IF(SUMPRODUCT(('Task Pause Log'!$B$2:$B$500=$A14)*('Task Pause Log'!$I$2:$I$500="Y"))>0,"Y","N") -> N
A15: T-M-006 | B15: Rajeshwar Pandey | C15: =IFERROR(VLOOKUP(B15,Employees!$A:$B,2,FALSE()),"") -> TBD - add phone number | D15: GST Form 3B Filing | E15: Monthly | F15: 20 | G15: 2026-09-01 | H15: 2026-12-31 | I15: Y | J15: =IFERROR(VLOOKUP(B15,Employees!$A:$D,4,FALSE()),"") -> Satyam Sharma | K15: =IFERROR(VLOOKUP(B15,Employees!$A:$E,5,FALSE()),"") -> 919798637485 | L15: 1 | M15: Accounts/Statutory | N15: From Accounts Checklist | O15: High | P15: =IF(SUMPRODUCT(('Task Pause Log'!$B$2:$B$500=$A15)*('Task Pause Log'!$I$2:$I$500="Y"))>0,"Y","N") -> N
A16: T-M-007 | B16: Rajeshwar Pandey | C16: =IFERROR(VLOOKUP(B16,Employees!$A:$B,2,FALSE()),"") -> TBD - add phone number | D16: GSTR-1 Outward Supply Filing | E16: Monthly | F16: 10 | G16: 2026-09-01 | H16: 2026-12-31 | I16: Y | J16: =IFERROR(VLOOKUP(B16,Employees!$A:$D,4,FALSE()),"") -> Satyam Sharma | K16: =IFERROR(VLOOKUP(B16,Employees!$A:$E,5,FALSE()),"") -> 919798637485 | L16: 1 | M16: Accounts/Statutory | N16: From Accounts Checklist | O16: High | P16: =IF(SUMPRODUCT(('Task Pause Log'!$B$2:$B$500=$A16)*('Task Pause Log'!$I$2:$I$500="Y"))>0,"Y","N") -> N
A17: T-M-008 | B17: Rajeshwar Pandey | C17: =IFERROR(VLOOKUP(B17,Employees!$A:$B,2,FALSE()),"") -> TBD - add phone number | D17: ESI Payment | E17: Monthly | F17: 15 | G17: 2026-09-01 | H17: 2026-12-31 | I17: Y | J17: =IFERROR(VLOOKUP(B17,Employees!$A:$D,4,FALSE()),"") -> Satyam Sharma | K17: =IFERROR(VLOOKUP(B17,Employees!$A:$E,5,FALSE()),"") -> 919798637485 | L17: 1 | M17: Accounts/Statutory | N17: From Accounts Checklist | O17: High | P17: =IF(SUMPRODUCT(('Task Pause Log'!$B$2:$B$500=$A17)*('Task Pause Log'!$I$2:$I$500="Y"))>0,"Y","N") -> N
A18: T-M-009 | B18: Rajeshwar Pandey | C18: =IFERROR(VLOOKUP(B18,Employees!$A:$B,2,FALSE()),"") -> TBD - add phone number | D18: Monthly PF Return | E18: Monthly | F18: 25 | G18: 2026-09-01 | H18: 2026-12-31 | I18: Y | J18: =IFERROR(VLOOKUP(B18,Employees!$A:$D,4,FALSE()),"") -> Satyam Sharma | K18: =IFERROR(VLOOKUP(B18,Employees!$A:$E,5,FALSE()),"") -> 919798637485 | L18: 1 | M18: Accounts/Statutory | N18: From Accounts Checklist | O18: High | P18: =IF(SUMPRODUCT(('Task Pause Log'!$B$2:$B$500=$A18)*('Task Pause Log'!$I$2:$I$500="Y"))>0,"Y","N") -> N
... A39: T-D-016 | B39: Yogesh Tomar | C39: =IFERROR(VLOOKUP(B39,Employees!$A:$B,2,FALSE()),"") -> TBD - add phone number | D39: Delegation tasks from CEO | E39: Daily | F39: Every day | G39: 2026-09-01 | H39: 2026-12-31 | I39: Y | J39: =IFERROR(VLOOKUP(B39,Employees!$A:$D,4,FALSE()),"") -> Satyam Sharma | K39: =IFERROR(VLOOKUP(B39,Employees!$A:$E,5,FALSE()),"") -> 919798637485 | L39: 1 | M39: Management | N39: From Yogesh ji Checklist (Sep 2026) | O39: High | P39: =IF(SUMPRODUCT(('Task Pause Log'!$B$2:$B$500=$A39)*('Task Pause Log'!$I$2:$I$500="Y"))>0,"Y","N") -> N

Sheet Checklist Templates
A1: Checklist Templates — predefined task lists per employee, pulled from job descriptions / manager input. Review, set final Cadence & Priority, then copy the row(s) you want into Task Master (do not paste formulas — Task Master's Employee Phone / Supervisor columns auto-fill via VLOOKUP once the Employee Name matches a row in Employees).
A2: Employee Name | B2: Department | C2: Designation | D2: Suggested Task Description | E2: Suggested Cadence | F2: Source | G2: Copied to Task Master (Y/N)
A3: Yogesh Tomar | B3: Operation | C3: Plant Head | D3: Daily recovery monitoring | E3: Daily | F3: Yogesh ji Checklist (provided Sep 2026) | G3: Y
A4: Yogesh Tomar | B4: Operation | C4: Plant Head | D4: Daily batch monitoring | E4: Daily | F4: Yogesh ji Checklist (provided Sep 2026) | G4: Y
A5: Yogesh Tomar | B5: Operation | C5: Plant Head | D5: Daily input output difference monitoring | E5: Daily | F5: Yogesh ji Checklist (provided Sep 2026) | G5: Y
A6: Yogesh Tomar | B6: Operation | C6: Plant Head | D6: Daily machine status monitoring | E6: Daily | F6: Yogesh ji Checklist (provided Sep 2026) | G6: Y
A7: Yogesh Tomar | B7: Operation | C7: Plant Head | D7: Daily department wise manpower monitoring | E7: Daily | F7: Yogesh ji Checklist (provided Sep 2026) | G7: Y
A8: Yogesh Tomar | B8: Operation | C8: Plant Head | D8: Raw material management and planning | E8: Daily | F8: Yogesh ji Checklist (provided Sep 2026) | G8: Y
A9: Yogesh Tomar | B9: Operation | C9: Plant Head | D9: Container incoming schedule monitoring | E9: Daily | F9: Yogesh ji Checklist (provided Sep 2026) | G9: Y
A10: Yogesh Tomar | B10: Operation | C10: Plant Head | D10: Material dispatch schedule monitoring (decide product to produce) | E10: Daily | F10: Yogesh ji Checklist (provided Sep 2026) | G10: Y
A11: Yogesh Tomar | B11: Operation | C11: Plant Head | D11: Consumable stock monitoring | E11: Daily | F11: Yogesh ji Checklist (provided Sep 2026) | G11: Y
A12: Yogesh Tomar | B12: Operation | C12: Plant Head | D12: Any project related work planning | E12: Daily | F12: Yogesh ji Checklist (provided Sep 2026) | G12: Y
A13: Yogesh Tomar | B13: Operation | C13: Plant Head | D13: HR related requirements and comment sheets | E13: Daily | F13: Yogesh ji Checklist (provided Sep 2026) | G13: Y
... A92: Mobin Ansari | B92: Dispatch | C92: Incharge | D92: Properly transfer and takeover shifts | E92: As Needed | F92: Job Description sheet (Job_Description_staff.xls) | G92: N
A93: Satish Bhumihar | B93: Production | C93: Incharge | D93: TBD - no job description on file yet. Add this employee's daily/weekly/monthly tasks here. | F93: Manager to fill | G93: N
A94: Rajeshwar Pandey | B94: Accounts | C94: Sr. Accountant | D94: TBD - no job description on file yet. Add this employee's daily/weekly/monthly tasks here. | F94: Manager to fill | G94: N
A95: Deb Kumar Nag | B95: Mech Maintenance | C95: HOD | D95: TBD - no job description on file yet. Add this employee's daily/weekly/monthly tasks here. | F95: Manager to fill | G95: N
A96: Om Kumar Choudhury | B96: Raw Material | C96: Incharge | D96: TBD - no job description on file yet. Add this employee's daily/weekly/monthly tasks here. | F96: Manager to fill | G96: N
A97: Ravi Anand | B97: HR | C97: Manager | D97: TBD - no job description on file yet. Add this employee's daily/weekly/monthly tasks here. | F97: Manager to fill | G97: N
A98: Shahin Sheikh | B98: Dispatch | C98: Incharge | D98: TBD - no job description on file yet. Add this employee's daily/weekly/monthly tasks here. | F98: Manager to fill | G98: N

Sheet Today's Assignment Queue
A1: Today's Assignment Queue — Review & Adjust Before Sending
A2: n8n drops today's auto-generated tasks here every morning. Untick 'Include Today' to drop one. Add a new row manually (Source=Manual) for an ad-hoc task. Nothing reaches the Senior Authority's form until this queue is Locked.
I3: Priority (auto-VLOOKUP) | J3: Locked At (system-set)
A4: Queue ID | B4: Employee Name | C4: Task Description | D4: Source (Auto/Manual) | E4: Task ID (if from Task Master) | F4: Include Today (Y/N) | G4: Supervisor Name | H4: Locked (Y/N) | I4: =IFERROR(VLOOKUP(E4,'Task Master'!$A:$O,15,FALSE()),"")
A5: Q-DEMO-001 | B5: Santosh Guddu | C5: Submit daily scrap procurement figures | D5: Auto | E5: T-D-001 | F5: Y | G5: Satyam Sharma | H5: N | I5: =IFERROR(VLOOKUP(E5,'Task Master'!$A:$O,15,FALSE()),"") -> Low
A6: Q-DEMO-002 | B6: Santosh Guddu | C6: Update daily inbound scrap weighbridge log | D6: Auto | E6: T-D-002 | F6: N | G6: Satyam Sharma | H6: N | I6: =IFERROR(VLOOKUP(E6,'Task Master'!$A:$O,15,FALSE()),"") -> Low
A7: Q-DEMO-003 | B7: Santosh Guddu | C7: One-off: verify vendor invoice #4521 | D7: Auto | F7: Y | G7: Satyam Sharma | H7: N | I7: =IFERROR(VLOOKUP(E7,'Task Master'!$A:$O,15,FALSE()),"")

Sheet Daily Checklist
A1: Checklist ID | B1: Date | C1: Task ID | D1: Employee Name | E1: Task Description | F1: Status | G1: Senior Remarks (from Form) | H1: Employee Response (via WhatsApp) | I1: Employee Response At | J1: Reminder Count | K1: Last Reminded | L1: Escalated (Y/N) | M1: Escalated At | N1: Supervisor Name | O1: Color Status | P1: Priority (auto-VLOOKUP) | Q1: Delivery Status (Sent/Delivered/Failed/Pending) | R1: Needs Manual Reconciliation (Y/N) | S1: Escalation Tier (1/2) | T1: Form Submission Timestamp
A2: CL-20260901-001 | B2: 2026-09-01 | C2: T-D-001 | D2: Santosh Guddu | E2: Submit daily scrap procurement figures | F2: Done | J2: 0 | L2: N | N2: Satyam Sharma | O2: =IF(F2="Done","Green",IF(L2="Y","Grey",IF(J2>0,"Orange",IF(F2="Not Done","Red","Yellow")))) -> Green | P2: =IFERROR(VLOOKUP(C2,'Task Master'!$A:$O,15,FALSE()),"") -> Low | Q2: Delivered | R2: N
A3: CL-20260901-002 | B3: 2026-09-01 | C3: T-D-002 | D3: Santosh Guddu | E3: Update daily inbound scrap weighbridge log | F3: Done | J3: 0 | L3: N | N3: Satyam Sharma | O3: =IF(F3="Done","Green",IF(L3="Y","Grey",IF(J3>0,"Orange",IF(F3="Not Done","Red","Yellow")))) -> Green | P3: =IFERROR(VLOOKUP(C3,'Task Master'!$A:$O,15,FALSE()),"") -> Low | Q3: Delivered | R3: N
A4: CL-20260901-003 | B4: 2026-09-01 | C4: T-M-001 | D4: Sushmita Mukherjee | E4: Submit monthly quality audit summary | F4: Not Done | G4: Pending clarification from HR | H4: Waiting on HR to confirm scope, will finish by EOD | I4: 2026-09-01 16:10 | J4: 3 | K4: 2026-09-01 15:00 | L4: Y | M4: 2026-09-01 17:00 | N4: Satyam Sharma | O4: =IF(F4="Done","Green",IF(L4="Y","Grey",IF(J4>0,"Orange",IF(F4="Not Done","Red","Yellow")))) -> Grey | P4: =IFERROR(VLOOKUP(C4,'Task Master'!$A:$O,15,FALSE()),"") -> Medium | Q4: Delivered | R4: N | S4: 1
A5: CL-20260902-004 | B5: 2026-09-02 | C5: T-D-001 | D5: Santosh Guddu | E5: Submit daily scrap procurement figures | F5: Done | J5: 0 | L5: N | N5: Satyam Sharma | O5: =IF(F5="Done","Green",IF(L5="Y","Grey",IF(J5>0,"Orange",IF(F5="Not Done","Red","Yellow")))) -> Green | P5: =IFERROR(VLOOKUP(C5,'Task Master'!$A:$O,15,FALSE()),"") -> Low | Q5: Delivered | R5: N
A6: CL-20260902-005 | B6: 2026-09-02 | C6: T-D-002 | D6: Santosh Guddu | E6: Update daily inbound scrap weighbridge log | F6: Not Done | G6: Missed - no remarks yet | J6: 1 | L6: N | N6: Satyam Sharma | O6: =IF(F6="Done","Green",IF(L6="Y","Grey",IF(J6>0,"Orange",IF(F6="Not Done","Red","Yellow")))) -> Orange | P6: =IFERROR(VLOOKUP(C6,'Task Master'!$A:$O,15,FALSE()),"") -> Low | Q6: Delivered | R6: N
A7: CL-20260903-006 | B7: 2026-09-03 | C7: T-D-001 | D7: Santosh Guddu | E7: Submit daily scrap procurement figures | F7: Done | J7: 0 | L7: N | N7: Satyam Sharma | O7: =IF(F7="Done","Green",IF(L7="Y","Grey",IF(J7>0,"Orange",IF(F7="Not Done","Red","Yellow")))) -> Green | P7: =IFERROR(VLOOKUP(C7,'Task Master'!$A:$O,15,FALSE()),"") -> Low | Q7: Delivered | R7: N
A8: CL-20260903-007 | B8: 2026-09-03 | C8: T-D-002 | D8: Santosh Guddu | E8: Update daily inbound scrap weighbridge log | F8: Done | J8: 0 | L8: N | N8: Satyam Sharma | O8: =IF(F8="Done","Green",IF(L8="Y","Grey",IF(J8>0,"Orange",IF(F8="Not Done","Red","Yellow")))) -> Green | P8: =IFERROR(VLOOKUP(C8,'Task Master'!$A:$O,15,FALSE()),"") -> Low | Q8: Delivered | R8: N
A9: CL-20260904-008 | B9: 2026-09-04 | C9: T-D-001 | D9: Santosh Guddu | E9: Submit daily scrap procurement figures | F9: Not Done | G9: Delayed - system down | H9: Sorry, weighbridge system was down till 2pm, updated manually now | I9: 2026-09-04 14:20 | J9: 1 | K9: 2026-09-04 13:00 | L9: N | N9: Satyam Sharma | O9: =IF(F9="Done","Green",IF(L9="Y","Grey",IF(J9>0,"Orange",IF(F9="Not Done","Red","Yellow")))) -> Orange | P9: =IFERROR(VLOOKUP(C9,'Task Master'!$A:$O,15,FALSE()),"") -> Low | Q9: Delivered | R9: N
A10: CL-20260904-009 | B10: 2026-09-04 | C10: T-D-002 | D10: Santosh Guddu | E10: Update daily inbound scrap weighbridge log | F10: Not Done | G10: Missed - no remarks yet | J10: 1 | L10: N | N10: Satyam Sharma | O10: =IF(F10="Done","Green",IF(L10="Y","Grey",IF(J10>0,"Orange",IF(F10="Not Done","Red","Yellow")))) -> Orange | P10: =IFERROR(VLOOKUP(C10,'Task Master'!$A:$O,15,FALSE()),"") -> Low | Q10: Delivered | R10: N
A11: CL-20260904-010 | B11: 2026-09-04 | C11: T-W-002 | D11: Chandan Kumar | E11: Machine downtime log review | F11: Done | J11: 0 | L11: N | N11: Satyam Sharma | O11: =IF(F11="Done","Green",IF(L11="Y","Grey",IF(J11>0,"Orange",IF(F11="Not Done","Red","Yellow")))) -> Green | P11: =IFERROR(VLOOKUP(C11,'Task Master'!$A:$O,15,FALSE()),"") -> Medium | Q11: Delivered | R11: N
A12: CL-20260905-011 | B12: 2026-09-05 | C12: T-D-001 | D12: Santosh Guddu | E12: Submit daily scrap procurement figures | F12: Done | J12: 0 | L12: N | N12: Satyam Sharma | O12: =IF(F12="Done","Green",IF(L12="Y","Grey",IF(J12>0,"Orange",IF(F12="Not Done","Red","Yellow")))) -> Green | P12: =IFERROR(VLOOKUP(C12,'Task Master'!$A:$O,15,FALSE()),"") -> Low | Q12: Delivered | R12: N
A13: CL-20260905-012 | B13: 2026-09-05 | C13: T-D-002 | D13: Santosh Guddu | E13: Update daily inbound scrap weighbridge log | F13: Done | J13: 0 | L13: N | N13: Satyam Sharma | O13: =IF(F13="Done","Green",IF(L13="Y","Grey",IF(J13>0,"Orange",IF(F13="Not Done","Red","Yellow")))) -> Green | P13: =IFERROR(VLOOKUP(C13,'Task Master'!$A:$O,15,FALSE()),"") -> Low | Q13: Delivered | R13: N

Sheet Employee Day-Wise Tracker
A1: Employee Day-Wise Submission Tracker
A2: Each cell = Done/Total tasks that day for that employee, color-coded. A partially completed day (e.g. 3/5) is shown exactly as that, not collapsed into pass/fail.
A4: Month Start Date (edit this): | B4: 46266
A6: Employee Name | B6: =IFERROR(TEXT($B$4+0,"dd-mmm"),"") -> 01-Sep | C6: =IFERROR(TEXT($B$4+1,"dd-mmm"),"") -> 02-Sep | D6: =IFERROR(TEXT($B$4+2,"dd-mmm"),"") -> 03-Sep | E6: =IFERROR(TEXT($B$4+3,"dd-mmm"),"") -> 04-Sep | F6: =IFERROR(TEXT($B$4+4,"dd-mmm"),"") -> 05-Sep | G6: =IFERROR(TEXT($B$4+5,"dd-mmm"),"") -> 06-Sep | H6: =IFERROR(TEXT($B$4+6,"dd-mmm"),"") -> 07-Sep | I6: =IFERROR(TEXT($B$4+7,"dd-mmm"),"") -> 08-Sep | J6: =IFERROR(TEXT($B$4+8,"dd-mmm"),"") -> 09-Sep | K6: =IFERROR(TEXT($B$4+9,"dd-mmm"),"") -> 10-Sep | L6: =IFERROR(TEXT($B$4+10,"dd-mmm"),"") -> 11-Sep | M6: =IFERROR(TEXT($B$4+11,"dd-mmm"),"") -> 12-Sep | N6: =IFERROR(TEXT($B$4+12,"dd-mmm"),"") -> 13-Sep | O6: =IFERROR(TEXT($B$4+13,"dd-mmm"),"") -> 14-Sep | P6: =IFERROR(TEXT($B$4+14,"dd-mmm"),"") -> 15-Sep | Q6: =IFERROR(TEXT($B$4+15,"dd-mmm"),"") -> 16-Sep | R6: =IFERROR(TEXT($B$4+16,"dd-mmm"),"") -> 17-Sep | S6: =IFERROR(TEXT($B$4+17,"dd-mmm"),"") -> 18-Sep | T6: =IFERROR(TEXT($B$4+18,"dd-mmm"),"") -> 19-Sep | U6: =IFERROR(TEXT($B$4+19,"dd-mmm"),"") -> 20-Sep | V6: =IFERROR(TEXT($B$4+20,"dd-mmm"),"") -> 21-Sep | W6: =IFERROR(TEXT($B$4+21,"dd-mmm"),"") -> 22-Sep | X6: =IFERROR(TEXT($B$4+22,"dd-mmm"),"") -> 23-Sep | Y6: =IFERROR(TEXT($B$4+23,"dd-mmm"),"") -> 24-Sep | Z6: =IFERROR(TEXT($B$4+24,"dd-mmm"),"") -> 25-Sep | AA6: =IFERROR(TEXT($B$4+25,"dd-mmm"),"") -> 26-Sep | AB6: =IFERROR(TEXT($B$4+26,"dd-mmm"),"") -> 27-Sep | AC6: =IFERROR(TEXT($B$4+27,"dd-mmm"),"") -> 28-Sep | AD6: =IFERROR(TEXT($B$4+28,"dd-mmm"),"") -> 29-Sep | AE6: =IFERROR(TEXT($B$4+29,"dd-mmm"),"") -> 30-Sep | AF6: =IFERROR(TEXT($B$4+30,"dd-mmm"),"") -> 01-Oct
A7: =IFERROR(IF(Employees!A2="","",Employees!A2),"") -> Yogesh Tomar | B7: =IF($A7="","",IF(SUMPRODUCT(('Daily Checklist'!$D$2:$D$2000=$A7)*(TEXT('Daily Checklist'!$B$2:$B$2000,"yyyy-mm-dd")=TEXT(($B$4+0),"yyyy-mm-dd")))=0,"-",IF(SUMPRODUCT(('Daily Checklist'!$D$2:$D$2000=$A7)*(TEXT('Daily Checklist'!$B$2:$B$2000,"yyyy-mm-dd")=TEXT(($B$4+0),"yyyy-mm-dd"))*('Daily Checklist'!$L$2:$L$2000="Y"))>0,SUMPRODUCT(('Daily Checklist'!$D$2:$D$2000=$A7)*(TEXT('Daily Checklist'!$B$2:$B$2000,"yyyy-mm-dd")=TEXT(($B$4+0),"yyyy-mm-dd"))*('Daily Checklist'!$F$2:$F$2000="Done"))&"/"&SUMPRODUCT(('Daily Checklist'!$D$2:$D$2000=$A7)*(TEXT('Daily Checklist'!$B$2:$B$2000,"yyyy-mm-dd")=TEXT(($B$4+0),"yyyy-mm-dd")))&" ESC",SUMPRODUCT(('Daily Checklist'!$D$2:$D$2000=$A7)*(TEXT('Daily Checklist'!$B$2:$B$2000,"yyyy-mm-dd")=TEXT(($B$4+0),"yyyy-mm-dd"))*('Daily Checklist'!$F$2:$F$2000="Done"))&"/"&SUMPRODUCT(('Daily Checklist'!$D$2:$D$2000=$A7)*(TEXT('Daily Checklist'!$B$2:$B$2000,"yyyy-mm-dd")=TEXT(($B$4+0),"yyyy-mm-dd")))))) -> - | C7: =IF($A7="","",IF(SUMPRODUCT(('Daily Checklist'!$D$2:$D$2000=$A7)*(TEXT('Daily Checklist'!$B$2:$B$2000,"yyyy-mm-dd")=TEXT(($B$4+1),"yyyy-mm-dd")))=0,"-",IF(SUMPRODUCT(('Daily Checklist'!$D$2:$D$2000=$A7)*(TEXT('Daily Checklist'!$B$2:$B$2000,"yyyy-mm-dd")=TEXT(($B$4+1),"yyyy-mm-dd"))*('Daily Checklist'!$L$2:$L$2000="Y"))>0,SUMPRODUCT(('Daily Checklist'!$D$2:$D$2000=$A7)*(TEXT('Daily Checklist'!$B$2:$B$2000,"yyyy-mm-dd")=TEXT(($B$4+1),"yyyy-mm-dd"))*('Daily Checklist'!$F$2:$F$2000="Done"))&"/"&SUMPRODUCT(('Daily Checklist'!$D$2:$D$2000=$A7)*(TEXT('Daily Checklist'!$B$2:$B$2000,"yyyy-mm-dd")=TEXT(($B$4+1),"yyyy-mm-dd")))&" ESC",SUMPRODUCT(('Daily Checklist'!$D$2:$D$2000=$A7)*(TEXT('Daily Checklist'!$B$2:$B$2000,"yyyy-mm-dd")=TEXT(($B$4+1),"yyyy-mm-dd"))*('Daily Checklist'!$F$2:$F$2000="Done"))&"/"&SUMPRODUCT(('Daily Checklist'!$D$2:$D$2000=$A7)*(TEXT('Daily Checklist'!$B$2:$B$2000,"yyyy-mm-dd")=TEXT(($B$4+1),"yyyy-mm-dd")))))) -> - | D7: =IF($A7="","",IF(SUMPRODUCT(('Daily Checklist'!$D$2:$D$2000=$A7)*(TEXT('Daily Checklist'!$B$2:$B$2000,"yyyy-mm-dd")=TEXT(($B$4+2),"yyyy-mm-dd")))=0,"-",IF(SUMPRODUCT(('Daily Checklist'!$D$2:$D$2000=$A7)*(TEXT('Daily Checklist'!$B$2:$B$2000,"yyyy-mm-dd")=TEXT(($B$4+2),"yyyy-mm-dd"))*('Daily Checklist'!$L$2:$L$2000="Y"))>0,SUMPRODUCT(('Daily Checklist'!$D$2:$D$2000=$A7)*(TEXT('Daily Checklist'!$B$2:$B$2000,"yyyy-mm-dd")=TEXT(($B$4+2),"yyyy-mm-dd"))*('Daily Checklist'!$F$2:$F$2000="Done"))&"/"&SUMPRODUCT(('Daily Checklist'!$D$2:$D$2000=$A7)*(TEXT('Daily Checklist'!$B$2:$B$2000,"yyyy-mm-dd")=TEXT(($B$4+2),"yyyy-mm-dd")))&" ESC",SUMPRODUCT(('Daily Checklist'!$D$2:$D$2000=$A7)*(TEXT('Daily Checklist'!$B$2:$B$2000,"yyyy-mm-dd")=TEXT(($B$4+2),"yyyy-mm-dd"))*('Daily Checklist'!$F$2:$F$2000="Done"))&"/"&SUMPRODUCT(('Daily Checklist'!$D$2:$D$2000=$A7)*(TEXT('Daily Checklist'!$B$2:$B$2000,"yyyy-mm-dd")=TEXT(($B$4+2),"yyyy-mm-dd")))))) -> - | E7: =IF($A7="","",IF(SUMPRODUCT(('Daily Checklist'!$D$2:$D$2000=$A7)*(TEXT('Daily Checklist'!$B$2:$B$2000,"yyyy-mm-dd")=TEXT(($B$4+3),"yyyy-mm-dd")))=0,"-",IF(SUMPRODUCT(('Daily Checklist'!$D$2:$D$2000=$A7)*(TEXT('Daily Checklist'!$B$2:$B$2000,"yyyy-mm-dd")=TEXT(($B$4+3),"yyyy-mm-dd"))*('Daily Checklist'!$L$2:$L$2000="Y"))>0,SUMPRODUCT(('Daily Checklist'!$D$2:$D$2000=$A7)*(TEXT('Daily Checklist'!$B$2:$B$2000,"yyyy-mm-dd")=TEXT(($B$4+3),"yyyy-mm-dd"))*('Daily Checklist'!$F$2:$F$2000="Done"))&"/"&SUMPRODUCT(('Daily Checklist'!$D$2:$D$2000=$A7)*(TEXT('Daily Checklist'!$B$2:$B$2000,"yyyy-mm-dd")=TEXT(($B$4+3),"yyyy-mm-dd")))&" ESC",SUMPRODUCT(('Daily Checklist'!$D$2:$D$2000=$A7)*(TEXT('Daily Checklist'!$B$2:$B$2000,"yyyy-mm-dd")=TEXT(($B$4+3),"yyyy-mm-dd"))*('Daily Checklist'!$F$2:$F$2000="Done"))&"/"&SUMPRODUCT(('Daily Checklist'!$D$2:$D$2000=$A7)*(TEXT('Daily Checklist'!$B$2:$B$2000,"yyyy-mm-dd")=TEXT(($B$4+3),"yyyy-mm-dd")))))) -> - | F7: =IF($A7="","",IF(SUMPRODUCT(('Daily Checklist'!$D$2:$D$2000=$A7)*(TEXT('Daily Checklist'!$B$2:$B$2000,"yyyy-mm-dd")=TEXT(($B$4+4),"yyyy-mm-dd")))=0,"-",IF(SUMPRODUCT(('Daily Checklist'!$D$2:$D$2000=$A7)*(TEXT('Daily Checklist'!$B$2:$B$2000,"yyyy-mm-dd")=TEXT(($B$4+4),"yyyy-mm-dd"))*('Daily Checklist'!$L$2:$L$2000="Y"))>0,SUMPRODUCT(('Daily Checklist'!$D$2:$D$2000=$A7)*(TEXT('Daily Checklist'!$B$2:$B$2000,"yyyy-mm-dd")=TEXT(($B$4+4),"yyyy-mm-dd"))*('Daily Checklist'!$F$2:$F$2000="Done"))&"/"&SUMPRODUCT(('Daily Checklist'!$D$2:$D$2000=$A7)*(TEXT('Daily Checklist'!$B$2:$B$2000,"yyyy-mm-dd")=TEXT(($B$4+4),"yyyy-mm-dd")))&" ESC",SUMPRODUCT(('Daily Checklist'!$D$2:$D$2000=$A7)*(TEXT('Daily Checklist'!$B$2:$B$2000,"yyyy-mm-dd")=TEXT(($B$4+4),"yyyy-mm-dd"))*('Daily Checklist'!$F$2:$F$2000="Done"))&"/"&SUMPRODUCT(('Daily Checklist'!$D$2:$D$2000=$A7)*(TEXT('Daily Checklist'!$B$2:$B$2000,"yyyy-mm-dd")=TEXT(($B$4+4),"yyyy-mm-dd")))))) -> - | G7: =IF($A7="","",IF(SUMPRODUCT(('Daily Checklist'!$D$2:$D$2000=$A7)*(TEXT('Daily Checklist'!$B$2:$B$2000,"yyyy-mm-dd")=TEXT(($B$4+5),"yyyy-mm-dd")))=0,"-",IF(SUMPRODUCT(('Daily Checklist'!$D$2:$D$2000=$A7)*(TEXT('Daily Checklist'!$B$2:$B$2000,"yyyy-mm-dd")=TEXT(($B$4+5),"yyyy-mm-dd"))*('Daily Checklist'!$L$2:$L$2000="Y"))>0,SUMPRODUCT(('Daily Checklist'!$D$2:$D$2000=$A7)*(TEXT('Daily Checklist'!$B$2:$B$2000,"yyyy-mm-dd")=TEXT(($B$4+5),"yyyy-mm-dd"))*('Daily Checklist'!$F$2:$F$2000="Done"))&"/"&SUMPRODUCT(('Daily Checklist'!$D$2:$D$2000=$A7)*(TEXT('Daily Checklist'!$B$2:$B$2000,"yyyy-mm-dd")=TEXT(($B$4+5),"yyyy-mm-dd")))&" ESC",SUMPRODUCT(('Daily Checklist'!$D$2:$D$2000=$A7)*(TEXT('Daily Checklist'!$B$2:$B$2000,"yyyy-mm-dd")=TEXT(($B$4+5),"yyyy-mm-dd"))*('Daily Checklist'!$F$2:$F$2000="Done"))&"/"&SUMPRODUCT(('Daily Checklist'!$D$2:$D$2000=$A7)*(TEXT('Daily Checklist'!$B$2:$B$2000,"yyyy-mm-dd")=TEXT(($B$4+5),"yyyy-mm-dd")))))) -> - | H7: =IF($A7="","",IF(SUMPRODUCT(('Daily Checklist'!$D$2:$D$2000=$A7)*(TEXT('Daily Checklist'!$B$2:$B$2000,"yyyy-mm-dd")=TEXT(($B$4+6),"yyyy-mm-dd")))=0,"-",IF(SUMPRODUCT(('Daily Checklist'!$D$2:$D$2000=$A7)*(TEXT('Daily Checklist'!$B$2:$B$2000,"yyyy-mm-dd")=TEXT(($B$4+6),"yyyy-mm-dd"))*('Daily Checklist'!$L$2:$L$2000="Y"))>0,SUMPRODUCT(('Daily Checklist'!$D$2:$D$2000=$A7)*(TEXT('Daily Checklist'!$B$2:$B$2000,"yyyy-mm-dd")=TEXT(($B$4+6),"yyyy-mm-dd"))*('Daily Checklist'!$F$2:$F$2000="Done"))&"/"&SUMPRODUCT(('Daily Checklist'!$D$2:$D$2000=$A7)*(TEXT('Daily Checklist'!$B$2:$B$2000,"yyyy-mm-dd")=TEXT(($B$4+6),"yyyy-mm-dd")))&" ESC",SUMPRODUCT(('Daily Checklist'!$D$2:$D$2000=$A7)*(TEXT('Daily Checklist'!$B$2:$B$2000,"yyyy-mm-dd")=TEXT(($B$4+6),"yyyy-mm-dd"))*('Daily Checklist'!$F$2:$F$2000="Done"))&"/"&SUMPRODUCT(('Daily Checklist'!$D$2:$D$2000=$A7)*(TEXT('Daily Checklist'!$B$2:$B$2000,"yyyy-mm-dd")=TEXT(($B$4+6),"yyyy-mm-dd")))))) -> - | I7: =IF($A7="","",IF(SUMPRODUCT(('Daily Checklist'!$D$2:$D$2000=$A7)*(TEXT('Daily Checklist'!$B$2:$B$2000,"yyyy-mm-dd")=TEXT(($B$4+7),"yyyy-mm-dd")))=0,"-",IF(SUMPRODUCT(('Daily Checklist'!$D$2:$D$2000=$A7)*(TEXT('Daily Checklist'!$B$2:$B$2000,"yyyy-mm-dd")=TEXT(($B$4+7),"yyyy-mm-dd"))*('Daily Checklist'!$L$2:$L$2000="Y"))>0,SUMPRODUCT(('Daily Checklist'!$D$2:$D$2000=$A7)*(TEXT('Daily Checklist'!$B$2:$B$2000,"yyyy-mm-dd")=TEXT(($B$4+7),"yyyy-mm-dd"))*('Daily Checklist'!$F$2:$F$2000="Done"))&"/"&SUMPRODUCT(('Daily Checklist'!$D$2:$D$2000=$A7)*(TEXT('Daily Checklist'!$B$2:$B$2000,"yyyy-mm-dd")=TEXT(($B$4+7),"yyyy-mm-dd")))&" ESC",SUMPRODUCT(('Daily Checklist'!$D$2:$D$2000=$A7)*(TEXT('Daily Checklist'!$B$2:$B$2000,"yyyy-mm-dd")=TEXT(($B$4+7),"yyyy-mm-dd"))*('Daily Checklist'!$F$2:$F$2000="Done"))&"/"&SUMPRODUCT(('Daily Checklist'!$D$2:$D$2000=$A7)*(TEXT('Daily Checklist'!$B$2:$B$2000,"yyyy-mm-dd")=TEXT(($B$4+7),"yyyy-mm-dd")))))) -> - | J7: =IF($A7="","",IF(SUMPRODUCT(('Daily Checklist'!$D$2:$D$2000=$A7)*(TEXT('Daily Checklist'!$B$2:$B$2000,"yyyy-mm-dd")=TEXT(($B$4+8),"yyyy-mm-dd")))=0,"-",IF(SUMPRODUCT(('Daily Checklist'!$D$2:$D$2000=$A7)*(TEXT('Daily Checklist'!$B$2:$B$2000,"yyyy-mm-dd")=TEXT(($B$4+8),"yyyy-mm-dd"))*('Daily Checklist'!$L$2:$L$2000="Y"))>0,SUMPRODUCT(('Daily Checklist'!$D$2:$D$2000=$A7)*(TEXT('Daily Checklist'!$B$2:$B$2000,"yyyy-mm-dd")=TEXT(($B$4+8),"yyyy-mm-dd"))*('Daily Checklist'!$F$2:$F$2000="Done"))&"/"&SUMPRODUCT(('Daily Checklist'!$D$2:$D$2000=$A7)*(TEXT('Daily Checklist'!$B$2:$B$2000,"yyyy-mm-dd")=TEXT(($B$4+8),"yyyy-mm-dd")))&" ESC",SUMPRODUCT(('Daily Checklist'!$D$2:$D$2000=$A7)*(TEXT('Daily Checklist'!$B$2:$B$2000,"yyyy-mm-dd")=TEXT(($B$4+8),"yyyy-mm-dd"))*('Daily Checklist'!$F$2:$F$2000="Done"))&"/"&SUMPRODUCT(('Daily Checklist'!$D$2:$D$2000=$A7)*(TEXT('Daily Checklist'!$B$2:$B$2000,"yyyy-mm-dd")=TEXT(($B$4+8),"yyyy-mm-dd")))))) -> - | K7: =IF($A7="","",IF(SUMPRODUCT(('Daily Checklist'!$D$2:$D$2000=$A7)*(TEXT('Daily Checklist'!$B$2:$B$2000,"yyyy-mm-dd")=TEXT(($B$4+9),"yyyy-mm-dd")))=0,"-",IF(SUMPRODUCT(('Daily Checklist'!$D$2:$D$2000=$A7)*(TEXT('Daily Checklist'!$B$2:$B$2000,"yyyy-mm-dd")=TEXT(($B$4+9),"yyyy-mm-dd"))*('Daily Checklist'!$L$2:$L$2000="Y"))>0,SUMPRODUCT(('Daily Checklist'!$D$2:$D$2000=$A7)*(TEXT('Daily Checklist'!$B$2:$B$2000,"yyyy-mm-dd")=TEXT(($B$4+9),"yyyy-mm-dd"))*('Daily Checklist'!$F$2:$F$2000="Done"))&"/"&SUMPRODUCT(('Daily Checklist'!$D$2:$D$2000=$A7)*(TEXT('Daily Checklist'!$B$2:$B$2000,"yyyy-mm-dd")=TEXT(($B$4+9),"yyyy-mm-dd")))&" ESC",SUMPRODUCT(('Daily Checklist'!$D$2:$D$2000=$A7)*(TEXT('Daily Checklist'!$B$2:$B$2000,"yyyy-mm-dd")=TEXT(($B$4+9),"yyyy-mm-dd"))*('Daily Checklist'!$F$2:$F$2000="Done"))&"/"&SUMPRODUCT(('Daily Checklist'!$D$2:$D$2000=$A7)*(TEXT('Daily Checklist'!$B$2:$B$2000,"yyyy-mm-dd")=TEXT(($B$4+9),"yyyy-mm-dd")))))) -> - | L7: =IF($A7="","",IF(SUMPRODUCT(('Daily Checklist'!$D$2:$D$2000=$A7)*(TEXT('Daily Checklist'!$B$2:$B$2000,"yyyy-mm-dd")=TEXT(($B$4+10),"yyyy-mm-dd")))=0,"-",IF(SUMPRODUCT(('Daily Checklist'!$D$2:$D$2000=$A7)*(TEXT('Daily Checklist'!$B$2:$B$2000,"yyyy-mm-dd")=TEXT(($B$4+10),"yyyy-mm-dd"))*('Daily Checklist'!$L$2:$L$2000="Y"))>0,SUMPRODUCT(('Daily Checklist'!$D$2:$D$2000=$A7)*(TEXT('Daily Checklist'!$B$2:$B$2000,"yyyy-mm-dd")=TEXT(($B$4+10),"yyyy-mm-dd"))*('Daily Checklist'!$F$2:$F$2000="Done"))&"/"&SUMPRODUCT(('Daily Checklist'!$D$2:$D$2000=$A7)*(TEXT('Daily Checklist'!$B$2:$B$2000,"yyyy-mm-dd")=TEXT(($B$4+10),"yyyy-mm-dd")))&" ESC",SUMPRODUCT(('Daily Checklist'!$D$2:$D$2000=$A7)*(TEXT('Daily Checklist'!$B$2:$B$2000,"yyyy-mm-dd")=TEXT(($B$4+10),"yyyy-mm-dd"))*('Daily Checklist'!$F$2:$F$2000="Done"))&"/"&SUMPRODUCT(('Daily Checklist'!$D$2:$D$2000=$A7)*(TEXT('Daily Checklist'!$B$2:$B$2000,"yyyy-mm-dd")=TEXT(($B$4+10),"yyyy-mm-dd")))))) -> - | M7: =IF($A7="","",IF(SUMPRODUCT(('Daily Checklist'!$D$2:$D$2000=$A7)*(TEXT('Daily Checklist'!$B$2:$B$2000,"yyyy-mm-dd")=TEXT(($B$4+11),"yyyy-mm-dd")))=0,"-",IF(SUMPRODUCT(('Daily Checklist'!$D$2:$D$2000=$A7)*(TEXT('Daily Checklist'!$B$2:$B$2000,"yyyy-mm-dd")=TEXT(($B$4+11),"yyyy-mm-dd"))*('Daily Checklist'!$L$2:$L$2000="Y"))>0,SUMPRODUCT(('Daily Checklist'!$D$2:$D$2000=$A7)*(TEXT('Daily Checklist'!$B$2:$B$2000,"yyyy-mm-dd")=TEXT(($B$4+11),"yyyy-mm-dd"))*('Daily Checklist'!$F$2:$F$2000="Done"))&"/"&SUMPRODUCT(('Daily Checklist'!$D$2:$D$2000=$A7)*(TEXT('Daily Checklist'!$B$2:$B$2000,"yyyy-mm-dd")=TEXT(($B$4+11),"yyyy-mm-dd")))&" ESC",SUMPRODUCT(('Daily Checklist'!$D$2:$D$2000=$A7)*(TEXT('Daily Checklist'!$B$2:$B$2000,"yyyy-mm-dd")=TEXT(($B$4+11),"yyyy-mm-dd"))*('Daily Checklist'!$F$2:$F$2000="Done"))&"/"&SUMPRODUCT(('Daily Checklist'!$D$2:$D$2000=$A7)*(TEXT('Daily Checklist'!$B$2:$B$2000,"yyyy-mm-dd")=TEXT(($B$4+11),"yyyy-mm-dd")))))) -> - | N7: =IF($A7="","",IF(SUMPRODUCT(('Daily Checklist'!$D$2:$D$2000=$A7)*(TEXT('Daily Checklist'!$B$2:$B$2000,"yyyy-mm-dd")=TEXT(($B$4+12),"yyyy-mm-dd")))=0,"-",IF(SUMPRODUCT(('Daily Checklist'!$D$2:$D$2000=$A7)*(TEXT('Daily Checklist'!$B$2:$B$2000,"yyyy-mm-dd")=TEXT(($B$4+12),"yyyy-mm-dd"))*('Daily Checklist'!$L$2:$L$2000="Y"))>0,SUMPRODUCT(('Daily Checklist'!$D$2:$D$2000=$A7)*(TEXT('Daily Checklist'!$B$2:$B$2000,"yyyy-mm-dd")=TEXT(($B$4+12),"yyyy-mm-dd"))*('Daily Checklist'!$F$2:$F$2000="Done"))&"/"&SUMPRODUCT(('Daily Checklist'!$D$2:$D$2000=$A7)*(TEXT('Daily Checklist'!$B$2:$B$2000,"yyyy-mm-dd")=TEXT(($B$4+12),"yyyy-mm-dd")))&" ESC",SUMPRODUCT(('Daily Checklist'!$D$2:$D$2000=$A7)*(TEXT('Daily Checklist'!$B$2:$B$2000,"yyyy-mm-dd")=TEXT(($B$4+12),"yyyy-mm-dd"))*('Daily Checklist'!$F$2:$F$2000="Done"))&"/"&SUMPRODUCT(('Daily Checklist'!$D$2:$D$2000=$A7)*(TEXT('Daily Checklist'!$B$2:$B$2000,"yyyy-mm-dd")=TEXT(($B$4+12),"yyyy-mm-dd")))))) -> - | O7: =IF($A7="","",IF(SUMPRODUCT(('Daily Checklist'!$D$2:$D$2000=$A7)*(TEXT('Daily Checklist'!$B$2:$B$2000,"yyyy-mm-dd")=TEXT(($B$4+13),"yyyy-mm-dd")))=0,"-",IF(SUMPRODUCT(('Daily Checklist'!$D$2:$D$2000=$A7)*(TEXT('Daily Checklist'!$B$2:$B$2000,"yyyy-mm-dd")=TEXT(($B$4+13),"yyyy-mm-dd"))*('Daily Checklist'!$L$2:$L$2000="Y"))>0,SUMPRODUCT(('Daily Checklist'!$D$2:$D$2000=$A7)*(TEXT('Daily Checklist'!$B$2:$B$2000,"yyyy-mm-dd")=TEXT(($B$4+13),"yyyy-mm-dd"))*('Daily Checklist'!$F$2:$F$2000="Done"))&"/"&SUMPRODUCT(('Daily Checklist'!$D$2:$D$2000=$A7)*(TEXT('Daily Checklist'!$B$2:$B$2000,"yyyy-mm-dd")=TEXT(($B$4+13),"yyyy-mm-dd")))&" ESC",SUMPRODUCT(('Daily Checklist'!$D$2:$D$2000=$A7)*(TEXT('Daily Checklist'!$B$2:$B$2000,"yyyy-mm-dd")=TEXT(($B$4+13),"yyyy-mm-dd"))*('Daily Checklist'!$F$2:$F$2000="Done"))&"/"&SUMPRODUCT(('Daily Checklist'!$D$2:$D$2000=$A7)*(TEXT('Daily Checklist'!$B$2:$B$2000,"yyyy-mm-dd")=TEXT(($B$4+13),"yyyy-mm-dd")))))) -> - | P7: =IF($A7="","",IF(SUMPRODUCT(('Daily Checklist'!$D$2:$D$2000=$A7)*(TEXT('Daily Checklist'!$B$2:$B$2000,"yyyy-mm-dd")=TEXT(($B$4+14),"yyyy-mm-dd")))=0,"-",IF(SUMPRODUCT(('Daily Checklist'!$D$2:$D$2000=$A7)*(TEXT('Daily Checklist'!$B$2:$B$2000,"yyyy-mm-dd")=TEXT(($B$4+14),"yyyy-mm-dd"))*('Daily Checklist'!$L$2:$L$2000="Y"))>0,SUMPRODUCT(('Daily Checklist'!$D$2:$D$2000=$A7)*(TEXT('Daily Checklist'!$B$2:$B$2000,"yyyy-mm-dd")=TEXT(($B$4+14),"yyyy-mm-dd"))*('Daily Checklist'!$F$2:$F$2000="Done"))&"/"&SUMPRODUCT(('Daily Checklist'!$D$2:$D$2000=$A7)*(TEXT('Daily Checklist'!$B$2:$B$2000,"yyyy-mm-dd")=TEXT(($B$4+14),"yyyy-mm-dd")))&" ESC",SUMPRODUCT(('Daily Checklist'!$D$2:$D$2000=$A7)*(TEXT('Daily Checklist'!$B$2:$B$2000,"yyyy-mm-dd")=TEXT(($B$4+14),"yyyy-mm-dd"))*('Daily Checklist'!$F$2:$F$2000="Done"))&"/"&SUMPRODUCT(('Daily Checklist'!$D$2:$D$2000=$A7)*(TEXT('Daily Checklist'!$B$2:$B$2000,"yyyy-mm-dd")=TEXT(($B$4+14),"yyyy-mm-dd")))))) -> - | Q7: =IF($A7="","",IF(SUMPRODUCT(('Daily Checklist'!$D$2:$D$2000=$A7)*(TEXT('Daily Checklist'!$B$2:$B$2000,"yyyy-mm-dd")=TEXT(($B$4+15),"yyyy-mm-dd")))=0,"-",IF(SUMPRODUCT(('Daily Checklist'!$D$2:$D$2000=$A7)*(TEXT('Daily Checklist'!$B$2:$B$2000,"yyyy-mm-dd")=TEXT(($B$4+15),"yyyy-mm-dd"))*('Daily Checklist'!$L$2:$L$2000="Y"))>0,SUMPRODUCT(('Daily Checklist'!$D$2:$D$2000=$A7)*(TEXT('Daily Checklist'!$B$2:$B$2000,"yyyy-mm-dd")=TEXT(($B$4+15),"yyyy-mm-dd"))*('Daily Checklist'!$F$2:$F$2000="Done"))&"/"&SUMPRODUCT(('Daily Checklist'!$D$2:$D$2000=$A7)*(TEXT('Daily Checklist'!$B$2:$B$2000,"yyyy-mm-dd")=TEXT(($B$4+15),"yyyy-mm-dd")))&" ESC",SUMPRODUCT(('Daily Checklist'!$D$2:$D$2000=$A7)*(TEXT('Daily Checklist'!$B$2:$B$2000,"yyyy-mm-dd")=TEXT(($B$4+15),"yyyy-mm-dd"))*('Daily Checklist'!$F$2:$F$2000="Done"))&"/"&SUMPRODUCT(('Daily Checklist'!$D$2:$D$2000=$A7)*(TEXT('Daily Checklist'!$B$2:$B$2000,"yyyy-mm-dd")=TEXT(($B$4+15),"yyyy-mm-dd")))))) -> - | R7: =IF($A7="","",IF(SUMPRODUCT(('Daily Checklist'!$D$2:$D$2000=$A7)*(TEXT('Daily Checklist'!$B$2:$B$2000,"yyyy-mm-dd")=TEXT(($B$4+16),"yyyy-mm-dd")))=0,"-",IF(SUMPRODUCT(('Daily Checklist'!$D$2:$D$2000=$A7)*(TEXT('Daily Checklist'!$B$2:$B$2000,"yyyy-mm-dd")=TEXT(($B$4+16),"yyyy-mm-dd"))*('Daily Checklist'!$L$2:$L$2000="Y"))>0,SUMPRODUCT(('Daily Checklist'!$D$2:$D$2000=$A7)*(TEXT('Daily Checklist'!$B$2:$B$2000,"yyyy-mm-dd")=TEXT(($B$4+16),"yyyy-mm-dd"))*('Daily Checklist'!$F$2:$F$2000="Done"))&"/"&SUMPRODUCT(('Daily Checklist'!$D$2:$D$2000=$A7)*(TEXT('Daily Checklist'!$B$2:$B$2000,"yyyy-mm-dd")=TEXT(($B$4+16),"yyyy-mm-dd")))&" ESC",SUMPRODUCT(('Daily Checklist'!$D$2:$D$2000=$A7)*(TEXT('Daily Checklist'!$B$2:$B$2000,"yyyy-mm-dd")=TEXT(($B$4+16),"yyyy-mm-dd"))*('Daily Checklist'!$F$2:$F$2000="Done"))&"/"&SUMPRODUCT(('Daily Checklist'!$D$2:$D$2000=$A7)*(TEXT('Daily Checklist'!$B$2:$B$2000,"yyyy-mm-dd")=TEXT(($B$4+16),"yyyy-mm-dd")))))) -> - | S7: =IF($A7="","",IF(SUMPRODUCT(('Daily Checklist'!$D$2:$D$2000=$A7)*(TEXT('Daily Checklist'!$B$2:$B$2000,"yyyy-mm-dd")=TEXT(($B$4+17),"yyyy-mm-dd")))=0,"-",IF(SUMPRODUCT(('Daily Checklist'!$D$2:$D$2000=$A7)*(TEXT('Daily Checklist'!$B$2:$B$2000,"yyyy-mm-dd")=TEXT(($B$4+17),"yyyy-mm-dd"))*('Daily Checklist'!$L$2:$L$2000="Y"))>0,SUMPRODUCT(('Daily Checklist'!$D$2:$D$2000=$A7)*(TEXT('Daily Checklist'!$B$2:$B$2000,"yyyy-mm-dd")=TEXT(($B$4+17),"yyyy-mm-dd"))*('Daily Checklist'!$F$2:$F$2000="Done"))&"/"&SUMPRODUCT(('Daily Checklist'!$D$2:$D$2000=$A7)*(TEXT('Daily Checklist'!$B$2:$B$2000,"yyyy-mm-dd")=TEXT(($B$4+17),"yyyy-mm-dd")))&" ESC",SUMPRODUCT(('Daily Checklist'!$D$2:$D$2000=$A7)*(TEXT('Daily Checklist'!$B$2:$B$2000,"yyyy-mm-dd")=TEXT(($B$4+17),"yyyy-mm-dd"))*('Daily Checklist'!$F$2:$F$2000="Done"))&"/"&SUMPRODUCT(('Daily Checklist'!$D$2:$D$2000=$A7)*(TEXT('Daily Checklist'!$B$2:$B$2000,"yyyy-mm-dd")=TEXT(($B$4+17),"yyyy-mm-dd")))))) -> - | T7: =IF($A7="","",IF(SUMPRODUCT(('Daily Checklist'!$D$2:$D$2000=$A7)*(TEXT('Daily Checklist'!$B$2:$B$2000,"yyyy-mm-dd")=TEXT(($B$4+18),"yyyy-mm-dd")))=0,"-",IF(SUMPRODUCT(('Daily Checklist'!$D$2:$D$2000=$A7)*(TEXT('Daily Checklist'!$B$2:$B$2000,"yyyy-mm-dd")=TEXT(($B$4+18),"yyyy-mm-dd"))*('Daily Checklist'!$L$2:$L$2000="Y"))>0,SUMPRODUCT(('Daily Checklist'!$D$2:$D$2000=$A7)*(TEXT('Daily Checklist'!$B$2:$B$2000,"yyyy-mm-dd")=TEXT(($B$4+18),"yyyy-mm-dd"))*('Daily Checklist'!$F$2:$F$2000="Done"))&"/"&SUMPRODUCT(('Daily Checklist'!$D$2:$D$2000=$A7)*(TEXT('Daily Checklist'!$B$2:$B$2000,"yyyy-mm-dd")=TEXT(($B$4+18),"yyyy-mm-dd")))&" ESC",SUMPRODUCT(('Daily Checklist'!$D$2:$D$2000=$A7)*(TEXT('Daily Checklist'!$B$2:$B$2000,"yyyy-mm-dd")=TEXT(($B$4+18),"yyyy-mm-dd"))*('Daily Checklist'!$F$2:$F$2000="Done"))&"/"&SUMPRODUCT(('Daily Checklist'!$D$2:$D$2000=$A7)*(TEXT('Daily Checklist'!$B$2:$B$2000,"yyyy-mm-dd")=TEXT(($B$4+18),"yyyy-mm-dd")))))) -> - | U7: =IF($A7="","",IF(SUMPRODUCT(('Daily Checklist'!$D$2:$D$2000=$A7)*(TEXT('Daily Checklist'!$B$2:$B$2000,"yyyy-mm-dd")=TEXT(($B$4+19),"yyyy-mm-dd")))=0,"-",IF(SUMPRODUCT(('Daily Checklist'!$D$2:$D$2000=$A7)*(TEXT('Daily Checklist'!$B$2:$B$2000,"yyyy-mm-dd")=TEXT(($B$4+19),"yyyy-mm-dd"))*('Daily Checklist'!$L$2:$L$2000="Y"))>0,SUMPRODUCT(('Daily Checklist'!$D$2:$D$2000=$A7)*(TEXT('Daily Checklist'!$B$2:$B$2000,"yyyy-mm-dd")=TEXT(($B$4+19),"yyyy-mm-dd"))*('Daily Checklist'!$F$2:$F$2000="Done"))&"/"&SUMPRODUCT(('Daily Checklist'!$D$2:$D$2000=$A7)*(TEXT('Daily Checklist'!$B$2:$B$2000,"yyyy-mm-dd")=TEXT(($B$4+19),"yyyy-mm-dd")))&" ESC",SUMPRODUCT(('Daily Checklist'!$D$2:$D$2000=$A7)*(TEXT('Daily Checklist'!$B$2:$B$2000,"yyyy-mm-dd")=TEXT(($B$4+19),"yyyy-mm-dd"))*('Daily Checklist'!$F$2:$F$2000="Done"))&"/"&SUMPRODUCT(('Daily Checklist'!$D$2:$D$2000=$A7)*(TEXT('Daily Checklist'!$B$2:$B$2000,"yyyy-mm-dd")=TEXT(($B$4+19),"yyyy-mm-dd")))))) -> - | V7: =IF($A7="","",IF(SUMPRODUCT(('Daily Checklist'!$D$2:$D$2000=$A7)*(TEXT('Daily Checklist'!$B$2:$B$2000,"yyyy-mm-dd")=TEXT(($B$4+20),"yyyy-mm-dd")))=0,"-",IF(SUMPRODUCT(('Daily Checklist'!$D$2:$D$2000=$A7)*(TEXT('Daily Checklist'!$B$2:$B$2000,"yyyy-mm-dd")=TEXT(($B$4+20),"yyyy-mm-dd"))*('Daily Checklist'!$L$2:$L$2000="Y"))>0,SUMPRODUCT(('Daily Checklist'!$D$2:$D$2000=$A7)*(TEXT('Daily Checklist'!$B$2:$B$2000,"yyyy-mm-dd")=TEXT(($B$4+20),"yyyy-mm-dd"))*('Daily Checklist'!$F$2:$F$2000="Done"))&"/"&SUMPRODUCT(('Daily Checklist'!$D$2:$D$2000=$A7)*(TEXT('Daily Checklist'!$B$2:$B$2000,"yyyy-mm-dd")=TEXT(($B$4+20),"yyyy-mm-dd")))&" ESC",SUMPRODUCT(('Daily Checklist'!$D$2:$D$2000=$A7)*(TEXT('Daily Checklist'!$B$2:$B$2000,"yyyy-mm-dd")=TEXT(($B$4+20),"yyyy-mm-dd"))*('Daily Checklist'!$F$2:$F$2000="Done"))&"/"&SUMPRODUCT(('Daily Checklist'!$D$2:$D$2000=$A7)*(TEXT('Daily Checklist'!$B$2:$B$2000,"yyyy-mm-dd")=TEXT(($B$4+20),"yyyy-mm-dd")))))) -> - | W7: =IF($A7="","",IF(SUMPRODUCT(('Daily Checklist'!$D$2:$D$2000=$A7)*(TEXT('Daily Checklist'!$B$2:$B$2000,"yyyy-mm-dd")=TEXT(($B$4+21),"yyyy-mm-dd")))=0,"-",IF(SUMPRODUCT(('Daily Checklist'!$D$2:$D$2000=$A7)*(TEXT('Daily Checklist'!$B$2:$B$2000,"yyyy-mm-dd")=TEXT(($B$4+21),"yyyy-mm-dd"))*('Daily Checklist'!$L$2:$L$2000="Y"))>0,SUMPRODUCT(('Daily Checklist'!$D$2:$D$2000=$A7)*(TEXT('Daily Checklist'!$B$2:$B$2000,"yyyy-mm-dd")=TEXT(($B$4+21),"yyyy-mm-dd"))*('Daily Checklist'!$F$2:$F$2000="Done"))&"/"&SUMPRODUCT(('Daily Checklist'!$D$2:$D$2000=$A7)*(TEXT('Daily Checklist'!$B$2:$B$2000,"yyyy-mm-dd")=TEXT(($B$4+21),"yyyy-mm-dd")))&" ESC",SUMPRODUCT(('Daily Checklist'!$D$2:$D$2000=$A7)*(TEXT('Daily Checklist'!$B$2:$B$2000,"yyyy-mm-dd")=TEXT(($B$4+21),"yyyy-mm-dd"))*('Daily Checklist'!$F$2:$F$2000="Done"))&"/"&SUMPRODUCT(('Daily Checklist'!$D$2:$D$2000=$A7)*(TEXT('Daily Checklist'!$B$2:$B$2000,"yyyy-mm-dd")=TEXT(($B$4+21),"yyyy-mm-dd")))))) -> - | X7: =IF($A7="","",IF(SUMPRODUCT(('Daily Checklist'!$D$2:$D$2000=$A7)*(TEXT('Daily Checklist'!$B$2:$B$2000,"yyyy-mm-dd")=TEXT(($B$4+22),"yyyy-mm-dd")))=0,"-",IF(SUMPRODUCT(('Daily Checklist'!$D$2:$D$2000=$A7)*(TEXT('Daily Checklist'!$B$2:$B$2000,"yyyy-mm-dd")=TEXT(($B$4+22),"yyyy-mm-dd"))*('Daily Checklist'!$L$2:$L$2000="Y"))>0,SUMPRODUCT(('Daily Checklist'!$D$2:$D$2000=$A7)*(TEXT('Daily Checklist'!$B$2:$B$2000,"yyyy-mm-dd")=TEXT(($B$4+22),"yyyy-mm-dd"))*('Daily Checklist'!$F$2:$F$2000="Done"))&"/"&SUMPRODUCT(('Daily Checklist'!$D$2:$D$2000=$A7)*(TEXT('Daily Checklist'!$B$2:$B$2000,"yyyy-mm-dd")=TEXT(($B$4+22),"yyyy-mm-dd")))&" ESC",SUMPRODUCT(('Daily Checklist'!$D$2:$D$2000=$A7)*(TEXT('Daily Checklist'!$B$2:$B$2000,"yyyy-mm-dd")=TEXT(($B$4+22),"yyyy-mm-dd"))*('Daily Checklist'!$F$2:$F$2000="Done"))&"/"&SUMPRODUCT(('Daily Checklist'!$D$2:$D$2000=$A7)*(TEXT('Daily Checklist'!$B$2:$B$2000,"yyyy-mm-dd")=TEXT(($B$4+22),"yyyy-mm-dd")))))) -> - | Y7: =IF($A7="","",IF(SUMPRODUCT(('Daily Checklist'!$D$2:$D$2000=$A7)*(TEXT('Daily Checklist'!$B$2:$B$2000,"yyyy-mm-dd")=TEXT(($B$4+23),"yyyy-mm-dd")))=0,"-",IF(SUMPRODUCT(('Daily Checklist'!$D$2:$D$2000=$A7)*(TEXT('Daily Checklist'!$B$2:$B$2000,"yyyy-mm-dd")=TEXT(($B$4+23),"yyyy-mm-dd"))*('Daily Checklist'!$L$2:$L$2000="Y"))>0,SUMPRODUCT(('Daily Checklist'!$D$2:$D$2000=$A7)*(TEXT('Daily Checklist'!$B$2:$B$2000,"yyyy-mm-dd")=TEXT(($B$4+23),"yyyy-mm-dd"))*('Daily Checklist'!$F$2:$F$2000="Done"))&"/"&SUMPRODUCT(('Daily Checklist'!$D$2:$D$2000=$A7)*(TEXT('Daily Checklist'!$B$2:$B$2000,"yyyy-mm-dd")=TEXT(($B$4+23),"yyyy-mm-dd")))&" ESC",SUMPRODUCT(('Daily Checklist'!$D$2:$D$2000=$A7)*(TEXT('Daily Checklist'!$B$2:$B$2000,"yyyy-mm-dd")=TEXT(($B$4+23),"yyyy-mm-dd"))*('Daily Checklist'!$F$2:$F$2000="Done"))&"/"&SUMPRODUCT(('Daily Checklist'!$D$2:$D$2000=$A7)*(TEXT('Daily Checklist'!$B$2:$B$2000,"yyyy-mm-dd")=TEXT(($B$4+23),"yyyy-mm-dd")))))) -> - | Z7: =IF($A7="","",IF(SUMPRODUCT(('Daily Checklist'!$D$2:$D$2000=$A7)*(TEXT('Daily Checklist'!$B$2:$B$2000,"yyyy-mm-dd")=TEXT(($B$4+24),"yyyy-mm-dd")))=0,"-",IF(SUMPRODUCT(('Daily Checklist'!$D$2:$D$2000=$A7)*(TEXT('Daily Checklist'!$B$2:$B$2000,"yyyy-mm-dd")=TEXT(($B$4+24),"yyyy-mm-dd"))*('Daily Checklist'!$L$2:$L$2000="Y"))>0,SUMPRODUCT(('Daily Checklist'!$D$2:$D$2000=$A7)*(TEXT('Daily Checklist'!$B$2:$B$2000,"yyyy-mm-dd")=TEXT(($B$4+24),"yyyy-mm-dd"))*('Daily Checklist'!$F$2:$F$2000="Done"))&"/"&SUMPRODUCT(('Daily Checklist'!$D$2:$D$2000=$A7)*(TEXT('Daily Checklist'!$B$2:$B$2000,"yyyy-mm-dd")=TEXT(($B$4+24),"yyyy-mm-dd")))&" ESC",SUMPRODUCT(('Daily Checklist'!$D$2:$D$2000=$A7)*(TEXT('Daily Checklist'!$B$2:$B$2000,"yyyy-mm-dd")=TEXT(($B$4+24),"yyyy-mm-dd"))*('Daily Checklist'!$F$2:$F$2000="Done"))&"/"&SUMPRODUCT(('Daily Checklist'!$D$2:$D$2000=$A7)*(TEXT('Daily Checklist'!$B$2:$B$2000,"yyyy-mm-dd")=TEXT(($B$4+24),"yyyy-mm-dd")))))) -> - | AA7: =IF($A7="","",IF(SUMPRODUCT(('Daily Checklist'!$D$2:$D$2000=$A7)*(TEXT('Daily Checklist'!$B$2:$B$2000,"yyyy-mm-dd")=TEXT(($B$4+25),"yyyy-mm-dd")))=0,"-",IF(SUMPRODUCT(('Daily Checklist'!$D$2:$D$2000=$A7)*(TEXT('Daily Checklist'!$B$2:$B$2000,"yyyy-mm-dd")=TEXT(($B$4+25),"yyyy-mm-dd"))*('Daily Checklist'!$L$2:$L$2000="Y"))>0,SUMPRODUCT(('Daily Checklist'!$D$2:$D$2000=$A7)*(TEXT('Daily Checklist'!$B$2:$B$2000,"yyyy-mm-dd")=TEXT(($B$4+25),"yyyy-mm-dd"))*('Daily Checklist'!$F$2:$F$2000="Done"))&"/"&SUMPRODUCT(('Daily Checklist'!$D$2:$D$2000=$A7)*(TEXT('Daily Checklist'!$B$2:$B$2000,"yyyy-mm-dd")=TEXT(($B$4+25),"yyyy-mm-dd")))&" ESC",SUMPRODUCT(('Daily Checklist'!$D$2:$D$2000=$A7)*(TEXT('Daily Checklist'!$B$2:$B$2000,"yyyy-mm-dd")=TEXT(($B$4+25),"yyyy-mm-dd"))*('Daily Checklist'!$F$2:$F$2000="Done"))&"/"&SUMPRODUCT(('Daily Checklist'!$D$2:$D$2000=$A7)*(TEXT('Daily Checklist'!$B$2:$B$2000,"yyyy-mm-dd")=TEXT(($B$4+25),"yyyy-mm-dd")))))) -> - | AB7: =IF($A7="","",IF(SUMPRODUCT(('Daily Checklist'!$D$2:$D$2000=$A7)*(TEXT('Daily Checklist'!$B$2:$B$2000,"yyyy-mm-dd")=TEXT(($B$4+26),"yyyy-mm-dd")))=0,"-",IF(SUMPRODUCT(('Daily Checklist'!$D$2:$D$2000=$A7)*(TEXT('Daily Checklist'!$B$2:$B$2000,"yyyy-mm-dd")=TEXT(($B$4+26),"yyyy-mm-dd"))*('Daily Checklist'!$L$2:$L$2000="Y"))>0,SUMPRODUCT(('Daily Checklist'!$D$2:$D$2000=$A7)*(TEXT('Daily Checklist'!$B$2:$B$2000,"yyyy-mm-dd")=TEXT(($B$4+26),"yyyy-mm-dd"))*('Daily Checklist'!$F$2:$F$2000="Done"))&"/"&SUMPRODUCT(('Daily Checklist'!$D$2:$D$2000=$A7)*(TEXT('Daily Checklist'!$B$2:$B$2000,"yyyy-mm-dd")=TEXT(($B$4+26),"yyyy-mm-dd")))&" ESC",SUMPRODUCT(('Daily Checklist'!$D$2:$D$2000=$A7)*(TEXT('Daily Checklist'!$B$2:$B$2000,"yyyy-mm-dd")=TEXT(($B$4+26),"yyyy-mm-dd"))*('Daily Checklist'!$F$2:$F$2000="Done"))&"/"&SUMPRODUCT(('Daily Checklist'!$D$2:$D$2000=$A7)*(TEXT('Daily Checklist'!$B$2:$B$2000,"yyyy-mm-dd")=TEXT(($B$4+26),"yyyy-mm-dd")))))) -> - | AC7: =IF($A7="","",IF(SUMPRODUCT(('Daily Checklist'!$D$2:$D$2000=$A7)*(TEXT('Daily Checklist'!$B$2:$B$2000,"yyyy-mm-dd")=TEXT(($B$4+27),"yyyy-mm-dd")))=0,"-",IF(SUMPRODUCT(('Daily Checklist'!$D$2:$D$2000=$A7)*(TEXT('Daily Checklist'!$B$2:$B$2000,"yyyy-mm-dd")=TEXT(($B$4+27),"yyyy-mm-dd"))*('Daily Checklist'!$L$2:$L$2000="Y"))>0,SUMPRODUCT(('Daily Checklist'!$D$2:$D$2000=$A7)*(TEXT('Daily Checklist'!$B$2:$B$2000,"yyyy-mm-dd")=TEXT(($B$4+27),"yyyy-mm-dd"))*('Daily Checklist'!$F$2:$F$2000="Done"))&"/"&SUMPRODUCT(('Daily Checklist'!$D$2:$D$2000=$A7)*(TEXT('Daily Checklist'!$B$2:$B$2000,"yyyy-mm-dd")=TEXT(($B$4+27),"yyyy-mm-dd")))&" ESC",SUMPRODUCT(('Daily Checklist'!$D$2:$D$2000=$A7)*(TEXT('Daily Checklist'!$B$2:$B$2000,"yyyy-mm-dd")=TEXT(($B$4+27),"yyyy-mm-dd"))*('Daily Checklist'!$F$2:$F$2000="Done"))&"/"&SUMPRODUCT(('Daily Checklist'!$D$2:$D$2000=$A7)*(TEXT('Daily Checklist'!$B$2:$B$2000,"yyyy-mm-dd")=TEXT(($B$4+27),"yyyy-mm-dd")))))) -> - | AD7: =IF($A7="","",IF(SUMPRODUCT(('Daily Checklist'!$D$2:$D$2000=$A7)*(TEXT('Daily Checklist'!$B$2:$B$2000,"yyyy-mm-dd")=TEXT(($B$4+28),"yyyy-mm-dd")))=0,"-",IF(SUMPRODUCT(('Daily Checklist'!$D$2:$D$2000=$A7)*(TEXT('Daily Checklist'!$B$2:$B$2000,"yyyy-mm-dd")=TEXT(($B$4+28),"yyyy-mm-dd"))*('Daily Checklist'!$L$2:$L$2000="Y"))>0,SUMPRODUCT(('Daily Checklist'!$D$2:$D$2000=$A7)*(TEXT('Daily Checklist'!$B$2:$B$2000,"yyyy-mm-dd")=TEXT(($B$4+28),"yyyy-mm-dd"))*('Daily Checklist'!$F$2:$F$2000="Done"))&"/"&SUMPRODUCT(('Daily Checklist'!$D$2:$D$2000=$A7)*(TEXT('Daily Checklist'!$B$2:$B$2000,"yyyy-mm-dd")=TEXT(($B$4+28),"yyyy-mm-dd")))&" ESC",SUMPRODUCT(('Daily Checklist'!$D$2:$D$2000=$A7)*(TEXT('Daily Checklist'!$B$2:$B$2000,"yyyy-mm-dd")=TEXT(($B$4+28),"yyyy-mm-dd"))*('Daily Checklist'!$F$2:$F$2000="Done"))&"/"&SUMPRODUCT(('Daily Checklist'!$D$2:$D$2000=$A7)*(TEXT('Daily Checklist'!$B$2:$B$2000,"yyyy-mm-dd")=TEXT(($B$4+28),"yyyy-mm-dd")))))) -> - | AE7: =IF($A7="","",IF(SUMPRODUCT(('Daily Checklist'!$D$2:$D$2000=$A7)*(TEXT('Daily Checklist'!$B$2:$B$2000,"yyyy-mm-dd")=TEXT(($B$4+29),"yyyy-mm-dd")))=0,"-",IF(SUMPRODUCT(('Daily Checklist'!$D$2:$D$2000=$A7)*(TEXT('Daily Checklist'!$B$2:$B$2000,"yyyy-mm-dd")=TEXT(($B$4+29),"yyyy-mm-dd"))*('Daily Checklist'!$L$2:$L$2000="Y"))>0,SUMPRODUCT(('Daily Checklist'!$D$2:$D$2000=$A7)*(TEXT('Daily Checklist'!$B$2:$B$2000,"yyyy-mm-dd")=TEXT(($B$4+29),"yyyy-mm-dd"))*('Daily Checklist'!$F$2:$F$2000="Done"))&"/"&SUMPRODUCT(('Daily Checklist'!$D$2:$D$2000=$A7)*(TEXT('Daily Checklist'!$B$2:$B$2000,"yyyy-mm-dd")=TEXT(($B$4+29),"yyyy-mm-dd")))&" ESC",SUMPRODUCT(('Daily Checklist'!$D$2:$D$2000=$A7)*(TEXT('Daily Checklist'!$B$2:$B$2000,"yyyy-mm-dd")=TEXT(($B$4+29),"yyyy-mm-dd"))*('Daily Checklist'!$F$2:$F$2000="Done"))&"/"&SUMPRODUCT(('Daily Checklist'!$D$2:$D$2000=$A7)*(TEXT('Daily Checklist'!$B$2:$B$2000,"yyyy-mm-dd")=TEXT(($B$4+29),"yyyy-mm-dd")))))) -> - | AF7: =IF($A7="","",IF(SUMPRODUCT(('Daily Checklist'!$D$2:$D$2000=$A7)*(TEXT('Daily Checklist'!$B$2:$B$2000,"yyyy-mm-dd")=TEXT(($B$4+30),"yyyy-mm-dd")))=0,"-",IF(SUMPRODUCT(('Daily Checklist'!$D$2:$D$2000=$A7)*(TEXT('Daily Checklist'!$B$2:$B$2000,"yyyy-mm-dd")=TEXT(($B$4+30),"yyyy-mm-dd"))*('Daily Checklist'!$L$2:$L$2000="Y"))>0,SUMPRODUCT(('Daily Checklist'!$D$2:$D$2000=$A7)*(TEXT('Daily Checklist'!$B$2:$B$2000,"yyyy-mm-dd")=TEXT(($B$4+30),"yyyy-mm-dd"))*('Daily Checklist'!$F$2:$F$2000="Done"))&"/"&SUMPRODUCT(('Daily Checklist'!$D$2:$D$2000=$A7)*(TEXT('Daily Checklist'!$B$2:$B$2000,"yyyy-mm-dd")=TEXT(($B$4+30),"yyyy-mm-dd")))&" ESC",SUMPRODUCT(('Daily Checklist'!$D$2:$D$2000=$A7)*(TEXT('Daily Checklist'!$B$2:$B$2000,"yyyy-mm-dd")=TEXT(($B$4+30),"yyyy-mm-dd"))*('Daily Checklist'!$F$2:$F$2000="Done"))&"/"&SUMPRODUCT(('Daily Checklist'!$D$2:$D$2000=$A7)*(TEXT('Daily Checklist'!$B$2:$B$2000,"yyyy-mm-dd")=TEXT(($B$4+30),"yyyy-mm-dd")))))) -> -
